<mujoco model="point_foot">
  <compiler angle="radian" autolimits="true"/>
  <statistic meansize="0.201559" extent="0.948112" center="0.00499457 0 -0.337764"/>
  
  <asset>
        <!--设置地板-->
        <texture name="grid" type="2d" builtin="checker" width="512" height="512" rgb1=".1 .2 .3" rgb2=".2 .3 .4"/>
        <material name="grid" texture="grid" texrepeat="1 1" texuniform="true" reflectance=".2"/>
    </asset>
    
    <option timestep="0.0005" integrator="RK4">
        <flag sensornoise="enable" />
    </option>
    
    <visual>
        <map force="0.1" zfar="30"/>
        <rgba haze="0.15 0.25 0.35 1"/>
        <global offwidth="2560" offheight="1440" elevation="-20" azimuth="120"/>
    </visual>
  
  <worldbody>
          <!--主光源（头顶）-->
      <light name="main_light" diffuse="2 2 2" specular="0.5 0.5 0.5" pos="0 0 40" dir="0 0 -1" castshadow="true"/>
      <!--辅助光源,四面八方-->
      <light name="aux_light1" diffuse=".8 .8 .8" pos=" 10 0 1" dir="-1 0 0" castshadow="false"/>
      <light name="aux_light2" diffuse=".8 .8 .8" pos="-10 0 1" dir=" 1 0 0" castshadow="false"/>
      <light name="aux_light3" diffuse=".8 .8 .8" pos="0  10 1" dir="0 -1 0" castshadow="false"/>
      <light name="aux_light4" diffuse=".8 .8 .8" pos="0 -10 1" dir="0  1 0" castshadow="false"/>
      <!--地板-->
      <geom name="floor" type="plane" size="0 0 0.05" material="grid"/>

       <body name="base_Link" pos="0 0 0.82" euler="0 0 0">
    <inertial pos="0.04576 0.00014 -0.16398"  mass="9.585" fullinertia="140110.479E-06 110641.449E-06 98944.542E-06 534.939E-06 28184.116E-06 -27.278E-06"/>
    <freejoint name="base_Link"/>
    <geom size="0.1325 0.13 0.09" pos="0.033 0 -0.07" type="box" rgba="0.79216 0.81961 0.93333 1"/>
    <site name="imu_site" pos="0 0 0" size="0.02" rgba="1 0 0 1" type="sphere" />

    <body name="abad_L_Link" pos="0.05556 0.105 -0.2602">
      <inertial pos="-0.06977 0.04479 0.00057" quat="0.595024 0.579772 0.394141 0.393019" mass="1.469" diaginertia="0.00252289 0.00208104 0.00139163"/>
      <joint name="abad_L_Joint" pos="0 0 0" axis="1 0 0" range="-0.38397 1.39626"/>
      <geom size="0.05 0.025" pos="0.03 0 0" quat="0.500398 0.5 0.499602 0.5" type="cylinder" rgba="0.79216 0.81961 0.93333 1"/>
      <body name="hip_L_Link" pos="-0.077 0.0205 0">
        <inertial pos="-0.02869 -0.0477 -0.03992" quat="0.853885 0.192797 0.226903 0.426877" mass="2.3" diaginertia="0.0233264 0.0230229 0.00277548"/>
        <joint name="hip_L_Joint" pos="0 0 0" axis="0 1 0" range="-1.01229 1.39626"/>
        <geom size="0.035 0.09" pos="-0.1 -0.02 -0.14" quat="0.965093 0 0.261909 0" type="cylinder" rgba="1 1 1 1"/>
        <body name="knee_L_Link" pos="-0.15 -0.0205 -0.25981">
          <inertial pos="0.0756053 0.00114274 -0.124051" quat="0.666349 -0.193556 -0.182961 0.696448" mass="0.730001" diaginertia="0.00961893 0.00954758 0.000224052"/>
          <joint name="knee_L_Joint" pos="0 0 0" axis="0 -1 0" range="-0.872665 1.36136"/>
          <geom size="0.015 0.13" pos="0.073 0 -0.12" quat="0.962425 0 -0.271547 0" type="cylinder" rgba="0.79216 0.81961 0.93333 1"/>
          <geom name="lfoot" size="0.032" pos="0.15 0 -0.25981" rgba="0.26667 0.26667 0.26667 1"/>
        </body>
      </body>
    </body>
    <body name="abad_R_Link" pos="0.05556 -0.105 -0.2602">
      <inertial pos="-0.06977 -0.04479 0.00057" quat="0.393019 0.394141 0.579772 0.595024" mass="1.469" diaginertia="0.00252289 0.00208104 0.00139163"/>
      <joint name="abad_R_Joint" pos="0 0 0" axis="1 0 0" range="-1.39626 0.38397"/>
      <geom size="0.05 0.025" pos="0.03 0 0" quat="0.500398 0.5 0.499602 0.5" type="cylinder" rgba="0.79216 0.81961 0.93333 1"/>
      <body name="hip_R_Link" pos="-0.077 -0.0205 0">
        <inertial pos="-0.02869 0.0477 -0.03992" quat="0.426877 0.226903 0.192797 0.853885" mass="2.3" diaginertia="0.0233264 0.0230229 0.00277548"/>
        <joint name="hip_R_Joint" pos="0 0 0" axis="0 -1 0" range="-1.39626 1.01229"/>
        <geom size="0.035 0.09" pos="-0.1 0.02 -0.14" quat="0.965093 0 0.261909 0" type="cylinder" rgba="1 1 1 1"/>
        <body name="knee_R_Link" pos="-0.15 0.0205 -0.25981">
          <inertial pos="0.0756053 -0.00114274 -0.124051" quat="0.696448 -0.182961 -0.193556 0.666349" mass="0.730001" diaginertia="0.00961893 0.00954758 0.000224052"/>
          <joint name="knee_R_Joint" pos="0 0 0" axis="0 1 0" range="-1.36136 0.872665"/>
          <geom size="0.015 0.13" pos="0.078 0 -0.12" quat="0.962425 0 -0.271547 0" type="cylinder" rgba="0.79216 0.81961 0.93333 1"/>
          <geom name="rfoot" size="0.032" pos="0.15 0 -0.25981" rgba="0.26667 0.26667 0.26667 1"/>
        </body>
      </body>
    </body>
    </body>
  </worldbody>

  <contact>
        <exclude body1="base_Link" body2="abad_L_Link"/>
        <exclude body1="base_Link" body2="hip_L_Link"/>
        <exclude body1="abad_L_Link"  body2="hip_L_Link"/>
        <exclude body1="hip_L_Link"  body2="knee_L_Link"/>

        <exclude body1="base_Link" body2="abad_R_Link"/>
        <exclude body1="base_Link" body2="hip_R_Link"/>
        <exclude body1="abad_R_Link"  body2="hip_R_Link"/>
        <exclude body1="hip_R_Link"  body2="knee_R_Link"/>

        <pair name="left_feet" geom1="lfoot" geom2="floor" condim="6" friction="2 2 0.05 0.05 0.05"/>
        <pair name="right_feet" geom1="rfoot" geom2="floor" condim="6" friction="2 2 0.05 0.05 0.05"/>
    </contact>

    <actuator>
        <!--腿-->
        <motor name="abad_L_Joint"   joint="abad_L_Joint"   gear="1" ctrllimited="true" ctrlrange="-60 60"/>
        <motor name="hip_L_Joint"  joint="hip_L_Joint"  gear="1" ctrllimited="true" ctrlrange="-60 60"/>
        <motor name="knee_L_Joint"  joint="knee_L_Joint"  gear="1" ctrllimited="true" ctrlrange="-60 60"/>
        <motor name="abad_R_Joint"   joint="abad_R_Joint"   gear="1" ctrllimited="true" ctrlrange="-60 60"/>
        <motor name="hip_R_Joint"  joint="hip_R_Joint"  gear="1" ctrllimited="true" ctrlrange="-60 60"/>
        <motor name="knee_R_Joint"  joint="knee_R_Joint"  gear="1" ctrllimited="true" ctrlrange="-60 60"/>
    </actuator>

    <sensor>
        <!--组合IMU-->
        <accelerometer name="imu_acc" site="imu_site" />
        <gyro name="imu_gyro" site="imu_site" />
        <framepos name="imu_pos" objtype="site" objname="imu_site" />
        <framelinvel name="imu_linvel" objtype="site" objname="imu_site" />
    </sensor>
</mujoco>
